<?xml version="1.0" ?>
<!-- =================================================================================== -->
<!-- |    This document was autogenerated by xacro from /home/twin_n/vrx_ws/src/wamv_gazebo/urdf/wamv_gazebo.urdf.xacro | -->
<!-- |    EDITING THIS FILE BY HAND IS NOT RECOMMENDED                                 | -->
<!-- =================================================================================== -->
<!-- Basic WAM-V with gazebo plugins for dynamics -->
<robot name="WAM-V">

  <link name="wamv/body_link">
    <inertial>
      <origin rpy="0 -0 0" xyz="0 0 0"/>
      <inertia ixx="1" ixy="0" ixz="0" iyy="1" iyz="0" izz="1"/>
      <mass value="40"/>
    </inertial>
    <visual>
      <origin rpy="0 -0 1.57" xyz="0 0 0"/>
      <geometry>
        <mesh filename="package://wamv_description/models/WAM-V-Base/mesh/base.dae"/>
      </geometry>
    </visual>
    <collision>
      <origin rpy="0 -0 1.57" xyz="0 0 0"/>
      <geometry>
        <mesh filename="package://wamv_description/models/WAM-V-Base/mesh/base.dae"/>
      </geometry>
    </collision>
  </link>

  <link name="wamv/left_propeller_link">
    <origin rpy="0 -0 1.57" xyz="0 0 0"/>
    <inertial>
      <origin rpy="0 -0 1.57" xyz="0 0 0"/>
      <inertia ixx="1" ixy="0" ixz="0" iyy="1" iyz="0" izz="1"/>
      <mass value=".1"/>
    </inertial>
    <mass value="0.1"/>
    <visual>
      <origin rpy="0 -0 1.57" xyz="0 0 0"/>
      <geometry>
        <mesh filename="package://wamv_description/models/WAM-V-Base/mesh/propeller.dae"/>
      </geometry>
    </visual>
    <collision>
      <origin rpy="0 -0 1.57" xyz="0 0 0"/>
      <geometry>
        <mesh filename="package://wamv_description/models/WAM-V-Base/mesh/propeller.dae"/>
      </geometry>
    </collision>
  </link>

  <link name="wamv/right_propeller_link">
    <inertial>
      <origin rpy="0 -0 0" xyz="0 0 0"/>
      <inertia ixx="1" ixy="0" ixz="0" iyy="1" iyz="0" izz="1"/>
      <mass value=".1"/>
    </inertial>
    <visual>
      <origin rpy="0 -0 1.57" xyz="0 0 0"/>
      <geometry>
        <mesh filename="package://wamv_description/models/WAM-V-Base/mesh/propeller.dae"/>
      </geometry>
    </visual>
    <collision>
      <origin rpy="0 -0 1.57" xyz="0 0 0"/>
      <geometry>
        <mesh filename="package://wamv_description/models/WAM-V-Base/mesh/propeller.dae"/>
      </geometry>
    </collision>
  </link>
<!-- 
  <link name="wamv/left_battery_link">
    <visual name="left_battery_visual">
      <origin rpy="0 0 0" xyz="0 -1.03 -.45"/>
      <geometry>
        <mesh filename="package://vrx_gazebo/models/battery/mesh/battery.dae"/>
      </geometry>
    </visual>
    <collision name="left_battery_collision">
      <origin rpy="0 0 0" xyz="0 0 .15"/>
      <geometry>
        <box size=".6 .4 .31"/>
      </geometry>
    </collision>
    <inertial>
      <origin rpy=" 0 0 0" xyz="0 0 .15"/>
      <mass value="23.5"/>
      <inertia ixx="0.5015291666666667" ixy="0" ixz="0" iyy="0.8931958333333333" iyz="0" izz="1.0183333333333333"/>
    </inertial>
  </link>
  <joint name="wamv/left_chasis_battery_joint" type="fixed">
    <origin rpy="0 0 0" xyz="0 1 0.45"/>
    <parent link="wamv/base_link"/>
    <child link="wamv/left_battery_link"/>
  </joint>
  <link name="wamv/right_battery_link">
    <visual name="right_battery_visual">
      <origin rpy="0 0 0" xyz="0 -1.03 -.45"/>
      <geometry>
        <mesh filename="package://vrx_gazebo/models/battery/mesh/battery.dae"/>
      </geometry>
    </visual>
    <collision name="right_battery_collision">
      <origin rpy="0 0 0" xyz="0 0 .15"/>
      <geometry>
        <box size=".6 .4 .31"/>
      </geometry>
    </collision>
    <inertial>
      <origin rpy=" 0 0 0" xyz="0 0 .15"/>
      <mass value="23.5"/>
      <inertia ixx="0.5015291666666667" ixy="0" ixz="0" iyy="0.8931958333333333" iyz="0" izz="1.0183333333333333"/>
    </inertial>
  </link>
  <joint name="wamv/right_chasis_battery_joint" type="fixed">
    <origin rpy="0 0 0" xyz="0 -1 0.45"/>
    <parent link="wamv/base_link"/>
    <child link="wamv/right_battery_link"/>
  </joint> -->
  <link name="wamv/base_link">
  </link>

  <joint name="wamv/dummy_joint" type="fixed">
    <parent link="wamv/base_link"/>
    <child link="wamv/body_link"/>
  </joint>


  <!-- <joint name="wamv/dummy_joint_2" type="fixed">
    <parent link="wamv/base_link"/>
    <child link="wamv/body_link"/>
  </joint> -->

  <!-- Basic model of the 16' WAM-V USV -->

  <link name="wamv/left_engine_link">
    <!-- <visual>
      <geometry>
        <mesh filename="package://wamv_description/models/engine/mesh/engine.dae"/>
      </geometry>
    </visual> -->
    <collision name="left_engine_vertical_axis_collision">
      <origin rpy="0 0 0" xyz="0 0 0"/>
      <geometry>
        <box size="0.2 0.15 0.83"/>
      </geometry>
    </collision>
    <collision name="left_engine_rear_end_collision">
      <origin rpy="0 0 0" xyz="-0.34 0 0.12"/>
      <geometry>
        <box size="0.12 0.15 0.12"/>
      </geometry>
    </collision>
    <inertial>
      <mass value="15"/>
      <inertia ixx="0.889245" ixy="0.0" ixz="0.0" iyy="0.911125" iyz="0.0" izz="0.078125"/>
    </inertial>
  </link>
  <!-- <link name="wamv/left_propeller_link">
    <visual>
      <geometry>
        <mesh filename="package://wamv_description/models/propeller/mesh/propeller.dae"/>
      </geometry>
    </visual>
    <collision name="left_propeller_collision">
      <origin rpy="0 1.57 0" xyz="-0.08 0 0"/>
      <geometry>
        <cylinder length="0.18" radius="0.24"/>
      </geometry>
    </collision>
    <inertial>
      <mass value="0.5"/>
      <inertia ixx="0.008545" ixy="0.0" ixz="0.0" iyy="0.008545" iyz="0.0" izz="0.0144"/>
    </inertial>
  </link> -->


  <joint name="wamv/left_chasis_engine_joint" type="revolute">
    <axis xyz="0 0 1"/>
    <limit effort="10" lower="0" upper="0" velocity="10"/>
    <origin rpy="0.0 0.0 0.0" xyz="-0.85 0.66 -0.2"/>
    <parent link="wamv/base_link"/>
    <child link="wamv/left_engine_link"/>
  </joint>
  <joint name="wamv/left_engine_propeller_joint" type="continuous">
    <axis rpy="0 0 0" xyz="1 0 0"/>
    <parent link="wamv/left_engine_link"/>
    <child link="wamv/left_propeller_link"/>
    <origin rpy="0 0 0" xyz="0 0 0"/>
    <limit effort="500" velocity="500"/>
    <dynamics damping="0.05" friction="0.05"/>
  </joint>


  <link name="wamv/right_engine_link">
    <!-- <visual>
      <geometry>
        <mesh filename="package://wamv_description/models/engine/mesh/engine.dae"/>
      </geometry>
    </visual> -->
    <collision name="right_engine_vertical_axis_collision">
      <origin rpy="0 0 0" xyz="-0.16 0 -0.24"/>
      <geometry>
        <box size="0.2 0.15 0.83"/>
      </geometry>
    </collision>
    <collision name="right_engine_rear_end_collision">
      <origin rpy="0 0 0" xyz="-0.34 0 0.12"/>
      <geometry>
        <box size="0.12 0.15 0.12"/>
      </geometry>
    </collision>
    <inertial>
      <mass value="15"/>
      <inertia ixx="0.889245" ixy="0.0" ixz="0.0" iyy="0.911125" iyz="0.0" izz="0.078125"/>
    </inertial>
  </link>
  <!-- <link name="wamv/right_propeller_link">
    <visual>
      <geometry>
        <mesh filename="package://wamv_description/models/propeller/mesh/propeller.dae"/>
      </geometry>
    </visual>
    <collision name="right_propeller_collision">
      <origin rpy="0 1.57 0" xyz="-0.08 0 0"/>
      <geometry>
        <cylinder length="0.18" radius="0.24"/>
      </geometry>
    </collision>
    <inertial>
      <mass value="0.5"/>
      <inertia ixx="0.008545" ixy="0.0" ixz="0.0" iyy="0.008545" iyz="0.0" izz="0.0144"/>
    </inertial>
  </link> -->
  <joint name="wamv/right_chasis_engine_joint" type="revolute">
    <axis xyz="0 0 1"/>
    <limit effort="0" lower="0" upper="0" velocity="0"/>
    <origin rpy="0.0 0.0 0.0" xyz="-0.85 -.7 -0.2"/>
    <parent link="wamv/base_link"/>
    <child link="wamv/right_engine_link"/>
  </joint>
  <joint name="wamv/right_engine_propeller_joint" type="continuous">
    <axis rpy="0 0 0" xyz="1 0 0"/>
    <parent link="wamv/right_engine_link"/>
    <child link="wamv/right_propeller_link"/>
    <origin rpy="0 0 0" xyz="0 0 0"/>
    <limit effort="200" velocity="200"/>
    <dynamics damping="0.05" friction="0.05"/>
  </joint>


  <!-- <link name="belt_link">
    <visual>
      <origin rpy="0 -0 0" xyz="0 0 0"/>
      <geometry>
        <mesh filename="package://wamv_description/models/WAM-V-Base/mesh/belt.dae"/>
      </geometry>
    </visual>
    <collision>
      <origin rpy="0 -0 0" xyz="0 0 0"/>
      <geometry>
        <mesh filename="package://wamv_description/models/WAM-V-Base/mesh/belt.dae"/>
      </geometry>
    </collision>
  </link>

  <joint name="belt_to_base_joint" type="fixed">
		<origin xyz="1.1 0 0.3" rpy="-2.82743 0 1.57"/>
    <parent link="wamv/base_link" />
    <child link="belt_link" />
  </joint> -->


  <link name="world" />

	<joint name="fixed_to_base" type="fixed">
		<parent link="wamv/body_link"/>
		<child link="world"/>
		<origin xyz="0.0 0.0 0.0" rpy="0.0 0.0 0"/>
	</joint>

  <joint name="fixed" type="fixed">
		<parent link="wamv/body_link"/>
		<child link="belt_visual"/>
		<origin xyz="0.0 0.0 .13" rpy="0.0 0.0 0"/>
	</joint>
	

	<link name="belt_visual">
		<inertial>
			<origin xyz="1.3 0 -0" rpy="0.32 0.0 1.57"/>
			<mass value=".01" />
			<inertia ixx="1" ixy="0" ixz="0" iyy="1" iyz="0" izz="1" />
		</inertial>
    <visual>
      <origin xyz="1.3 0 .05" rpy="0.32 0.0 1.57"/>
      <geometry>
        <mesh filename="package://wamv_description/models/WAM-V-Base/mesh/belt.dae"/>
      </geometry>
    </visual>
	</link>




	<joint name="belt_joint" type="prismatic">
		<origin xyz="1.6 0 .03" rpy="0.35 0.0 1.57"/>
		<parent link="world"/>
		<child link="belt_moving"/>
		<axis xyz="0 1 0"/>
		<limit lower="0.0" upper="1" effort="1000" velocity="1000"/>
	</joint>

	<link name="belt_moving">
		<inertial>
			<origin xyz="0.0 0.0 0.0" rpy="0 0.0 0.0"/>
			<mass value=".0001"/>
			<inertia ixx="0.0" ixy="0.0" ixz="0.0" iyy="0.0" iyz="0.0" izz="0.0"/>
		</inertial>
		<collision>
			<origin xyz="0.0 0.0 0.0" rpy="0 0.0 0.0"/>
			<geometry>
				<box size="1 1.2 0.1"/>
			</geometry>
		</collision>
	</link>

  <gazebo reference="belt_moving">
    <collision>
      <surface>
        <friction>
          <ode>
            <mu>1</mu>
            <mu2>1</mu2>
            <slip1>0</slip1>
            <slip2>0</slip2>
          </ode>
        </friction>
      </surface>
    </collision>
  </gazebo>

	<gazebo>
		<plugin name="conveyor_belt_plugin" filename="libROSConveyorBeltPlugin.so">
			<robot_namespace>/</robot_namespace>
			<link>belt_moving</link>
			<power>20</power>
			<max_velocity>1.0</max_velocity>
		</plugin>
	</gazebo>


  <gazebo>
    <plugin filename="libusv_gazebo_thrust_plugin.so" name="wamv_gazebo_thrust">
      <cmdTimeout>1.0</cmdTimeout>
      <robotNamespace>wamv</robotNamespace>
      <thruster>
        <!-- Required Parameters -->
        <linkName>wamv/left_propeller_link</linkName>
        <propJointName>wamv/left_engine_propeller_joint</propJointName>
        <engineJointName>wamv/left_chasis_engine_joint</engineJointName>
        <cmdTopic>thrusters/left_thrust_cmd</cmdTopic>
        <angleTopic>thrusters/left_thrust_angle</angleTopic>
        <enableAngle>False</enableAngle>
        <!-- Optional Parameters -->
        <mappingType>1</mappingType>
        <maxCmd>1.0</maxCmd>
        <maxForceFwd>1050.0</maxForceFwd>
        <maxForceRev>-150.0</maxForceRev>
        <maxAngle>0</maxAngle>
      </thruster>
      <thruster>
        <!-- Required Parameters -->
        <linkName>wamv/right_propeller_link</linkName>
        <propJointName>wamv/right_engine_propeller_joint</propJointName>
        <engineJointName>wamv/right_chasis_engine_joint</engineJointName>
        <cmdTopic>thrusters/right_thrust_cmd</cmdTopic>
        <angleTopic>thrusters/right_thrust_angle</angleTopic>
        <enableAngle>True</enableAngle>
        <!-- Optional Parameters -->
        <mappingType>1</mappingType>
        <maxCmd>1.0</maxCmd>
        <maxForceFwd>1050.0</maxForceFwd>
        <maxForceRev>-1050.0</maxForceRev>
        <maxAngle>0</maxAngle>
      </thruster>
    </plugin>
  </gazebo>

  <!--Gazebo Plugin for simulating WAM-V dynamics-->
  <gazebo>
    <plugin filename="libusv_gazebo_dynamics_plugin.so" name="usv_dynamics_wamv_dynamics_plugin">
      <bodyName>wamv/base_link</bodyName>
      <!-- Must be same as the ocean model!-->
      <waterLevel>0</waterLevel>
      <waterDensity>997.8</waterDensity>
      <!-- Added mass -->
      <xDotU>0.0</xDotU>
      <yDotV>0.0</yDotV>
      <nDotR>0.0</nDotR>
      <!-- Linear and quadratic drag -->
      <xU>51.3</xU>
      <xUU>72.4</xUU>
      <yV>40.0</yV>
      <yVV>0.0</yVV>
      <zW>500.0</zW>
      <kP>50.0</kP>
      <mQ>50.0</mQ>
      <nR>400.0</nR>
      <nRR>0.0</nRR>
      <!-- General dimensions -->
      <!--<boatArea>2.2</boatArea>-->
      <hullRadius>0.213</hullRadius>
      <boatWidth>2.4</boatWidth>
      <boatLength>4.9</boatLength>
      <!-- Length discretization, AKA, "N" -->
      <length_n>2</length_n>
      <!-- Wave model -->
      <wave_model>ocean_waves</wave_model>
    </plugin>
  </gazebo>

  <link name="wamv/gps_wamv_link">
    <collision name="gps_wamv_collision_base">
      <origin rpy="0 0 0" xyz="0 0 0.025"/>
      <geometry>
        <cylinder length="0.05" radius="0.015"/>
      </geometry>
    </collision>
    <collision name="gps_wamv_collision_antenna">
      <origin rpy="0 0 0" xyz="0 0 0.11"/>
      <geometry>
        <cylinder length="0.1" radius="0.15"/>
      </geometry>
    </collision>
    <inertial>
      <mass value="1"/>
      <inertia ixx="0.006458" ixy="0.0" ixz="0.0" iyy="0.006458" iyz="0.0" izz="0.01125"/>
    </inertial>
  </link>
  <joint name="wamv/gps_wamv_joint" type="revolute">
    <axis xyz="0 0 1"/>
    <limit effort="1000.0" lower="0.0" upper="0" velocity="0"/>
    <origin rpy="0 0 0" xyz="-0.85 0 1.3"/>
    <parent link="wamv/base_link"/>
    <child link="wamv/gps_wamv_link"/>
  </joint>

  <gazebo>
    <plugin filename="libhector_gazebo_ros_gps.so" name="gps_plugin_gps_wamv">
      <updateRate>15</updateRate>
      <alwaysOn>true</alwaysOn>
      <bodyName>wamv/gps_wamv_link</bodyName>
      <!-- Manually prepend namespace to tf frame. -->
      <frameId>wamv/gps_wamv_link</frameId>
      <topicName>wamv/sensors/gps/gps/fix</topicName>
      <!-- Note that the hector_gazebo_ros_gps plugin uses NWU coordinates
             for reporting velocities.  This may cause problems if localization
             requires velocity in ENU.
             See Issue #64 in VRX project for details
             https://bitbucket.org/osrf/vrx/issues/64 -->
      <velocityTopicName>wamv/sensors/gps/gps/fix_velocity</velocityTopicName>
      <!-- Location of origin of Gazebo Sand Island map -->
      <referenceLatitude>-33.724223</referenceLatitude>
      <referenceLongitude>150.679736</referenceLongitude>
      <referenceAltitude>0.0</referenceAltitude>
      <referenceHeading>270</referenceHeading>
      <offset>0.0 0.0 0.0</offset>
      <drift>0.0 0.0 0.0</drift>
      <gaussianNoise>0 0 0</gaussianNoise>
      <velocityOffset>0.0 0.0 0.0</velocityOffset>
      <velocityDrift>0.0 0.0 0.0</velocityDrift>
      <velocityGaussianNoise>0.0 0.0 0.0</velocityGaussianNoise>
    </plugin>
  </gazebo>

  <link name="wamv/imu_wamv_link">
    <inertial>
      <mass value="0.1"/>
      <inertia ixx="0.000083" ixy="0.0" ixz="0.0" iyy="0.000083" iyz="0.0" izz="0.0125"/>
    </inertial>
  </link>
  <joint name="wamv/imu_wamv_joint" type="revolute">
    <axis xyz="0 0 1"/>
    <limit effort="1000.0" lower="0.0" upper="0" velocity="0"/>
    <origin rpy="0 0 0" xyz="0.3 -0.2 1.3"/>
    <parent link="wamv/base_link"/>
    <child link="wamv/imu_wamv_link"/>
  </joint>

  <gazebo>
    <plugin filename="libhector_gazebo_ros_imu.so" name="imu_plugin_imu_wamv">
      <updateRate>15</updateRate>
      <bodyName>wamv/imu_wamv_link</bodyName>
      <topicName>wamv/sensors/imu/imu/data</topicName>
      <serviceName>wamv/sensors/imu_service</serviceName>
      <!-- Manually prepend namespace to tf frame. -->
      <frameId>wamv/imu_wamv_link</frameId>
      <alwaysOn>true</alwaysOn>
      <accelOffset>0.0 0.0 0.0</accelOffset>
      <accelDrift>0.0 0.0 0.0</accelDrift>
      <accelDriftFrequency>0.00027 0.00027 0.000027</accelDriftFrequency>
      <accelGaussianNoise>0.0 0.0 0.0</accelGaussianNoise>
      <rateOffset>0.0 0.0 0.0</rateOffset>
      <rateDrift>0.0 0.0 0.0</rateDrift>
      <rateDriftFrequency>0.00027 0.00027 0.000027</rateDriftFrequency>
      <rateGaussianNoise>0.0 0.0 0.0</rateGaussianNoise>
      <yawOffset>0.0</yawOffset>
      <yawDrift>0.0</yawDrift>
      <yawDriftFrequency>0.00027</yawDriftFrequency>
      <yawGaussianNoise>0.0</yawGaussianNoise>
    </plugin>
  </gazebo>


  <!-- 3d lidar sensor -->
  <link name="wamv/lidar_wamv_link">
    <visual name="lidar_wamv_visual">
      <origin rpy="0 0 0" xyz="0 0 0"/>
      <geometry>
        <mesh filename="package://wamv_description/models/WAM-V-Base/mesh/sensor.dae"/>
      </geometry>
    </visual>
    <collision name="lidar_wamv_collision">
      <geometry>
        <cylinder length="0.075" radius="0.055"/>
      </geometry>
    </collision>
    <inertial>
      <mass value="1"/>
      <inertia ixx="0.00109375" ixy="0" ixz="0" iyy="0.00109375" iyz="0" izz="0.00125"/>
    </inertial>
  </link>
  <!-- Sensor base_link to lidar joint -->
  <joint name="wamv/lidar_wamv_post_arm_to_lidar_wamv_joint" type="fixed">
    <origin rpy="0 0 1.57" xyz="0.751596 0 0.785158"/>
    <parent link="wamv/base_link"/>
    <child link="wamv/lidar_wamv_link"/>
  </joint>

  <gazebo reference="wamv/lidar_wamv_link">
    <sensor name="lidar_wamv_sensor" type="gpu_ray">
      <update_rate>10</update_rate>
      <ray>
        <scan>
          <horizontal>
            <samples>18750.0</samples>
            <resolution>0.1</resolution>
            <min_angle>-3.1416</min_angle>
            <max_angle>-3.1416</max_angle>
          </horizontal>
          <vertical>
            <samples>16</samples>
            <resolution>1</resolution>
            <min_angle>-0.0872665</min_angle>
            <max_angle>0.0872665</max_angle>
          </vertical>
        </scan>
        <range>
          <min>0.1</min>
          <max>130</max>
        </range>
        <noise>
          <type>gaussian</type>
          <mean>0.0</mean>
          <stddev>0.01</stddev>
        </noise>
      </ray>
      <plugin filename="libgazebo_ros_velodyne_gpu_laser.so" name="lidar_wamv_plugin">
        <topicName>wamv/sensors/lidars/lidar_wamv/points</topicName>
        <frameName>wamv/lidar_wamv_link</frameName>
        <min_intensity>0</min_intensity>
      </plugin>
    </sensor>
  </gazebo>
  <!--specs for 16 beam lidar are implemented by default.
          See wamv_3d_lidar for those-->
  <!-- <link name="wamv/cpu_cases_link">
    <visual name="cpu_cases_visual">
      <origin rpy="0 0 0" xyz="0.073 0 -1.53"/>
      <geometry>
        <mesh filename="package://vrx_gazebo/models/cpu_cases/mesh/cpu_cases.dae"/>
      </geometry>
    </visual>
    <collision name="cpu_case_1_collision">
      <origin rpy="0 0 0" xyz="0.185 0 0"/>
      <geometry>
        <box size="0.595 0.83 0.47"/>
      </geometry>
    </collision>
    <collision name="cpu_case_2_collision">
      <origin rpy="0 0 0" xyz="-0.3 0 -0.092"/>
      <geometry>
        <box size="0.375 0.64 0.28"/>
      </geometry>
    </collision>
    <inertial>
      <mass value="20"/>
      <inertia ixx="1.51633333333333" ixy="0" ixz="0" iyy="1.93633333333333" iyz="0" izz="2.71633333333333"/>
    </inertial>
  </link>
  <joint name="wamv/chasis_cpu_cases_joint" type="fixed">
    <origin rpy="0 0 0" xyz="-0.15 0 1.53"/>
    <parent link="wamv/base_link"/>
    <child link="wamv/cpu_cases_link"/>
  </joint> -->

</robot>
